fun main (){

    println("iniciando proga")
    try {
        println("dentro del try")
        val lista1 :Int = 1
        lista1 = 7


    }
    catch (e:Exception){
        println("dentro del catch")
    }





}